<?xml version="1.0" ?>
<sdf version="1.6">
  <world name="obstacle_avoidance_world">
    
    <!-- Physics engine -->
    <physics type="ode">
      <max_step_size>0.001</max_step_size>
      <real_time_factor>1</real_time_factor>
    </physics>
    
    <!-- Light source -->
    <light type="directional" name="sun">
      <cast_shadows>true</cast_shadows>
      <pose frame="">0 0 10 0 0 0</pose>
      <diffuse>0.8 0.8 0.8 1</diffuse>
      <specular>0.2 0.2 0.2 1</specular>
      <attenuation>
        <range>1000</range>
        <constant>0.9</constant>
        <linear>0.01</linear>
        <quadratic>0.001</quadratic>
      </attenuation>
      <direction>-0.5 0.1 -0.9</direction>
    </light>
    
    <!-- Ground plane -->
    <model name="ground_plane">
      <static>true</static>
      <link name="link">
        <collision name="collision">
          <geometry>
            <plane>
              <normal>0 0 1</normal>
              <size>100 100</size>
            </plane>
          </geometry>
        </collision>
        <visual name="visual">
          <geometry>
            <plane>
              <normal>0 0 1</normal>
              <size>100 100</size>
            </plane>
          </geometry>
          <material>
            <script>
              <uri>file://media/materials/scripts/gazebo.material</uri>
              <name>Gazebo/Grey</name>
            </script>
          </material>
        </visual>
      </link>
    </model>
    
    <!-- Simple robot with lidar (point at 0,0,0.2m) -->
    <model name="mobile_robot">
      <pose frame="">0 0 0 0 0 0</pose>
      <link name="base_link">
        <inertial>
          <mass>10.0</mass>
          <inertia>
            <ixx>0.1</ixx>
            <ixy>0</ixy>
            <ixz>0</ixz>
            <iyy>0.1</iyy>
            <iyz>0</iyz>
            <izz>0.05</izz>
          </inertia>
        </inertial>
        
        <!-- Main body -->
        <collision name="body_collision">
          <geometry>
            <box>
              <size>0.3 0.3 0.2</size>
            </box>
          </geometry>
        </collision>
        <visual name="body_visual">
          <geometry>
            <box>
              <size>0.3 0.3 0.2</size>
            </box>
          </geometry>
          <material>
            <script>
              <uri>file://media/materials/scripts/gazebo.material</uri>
              <name>Gazebo/Blue</name>
            </script>
          </material>
        </visual>
        
        <!-- Lidar sensor (Ray sensor for 2D scanning) -->
        <sensor type="ray" name="lidar">
          <pose>0 0 0.15 0 0 0</pose>
          <visualize>true</visualize>
          <update_rate>10</update_rate>
          <ray>
            <scan>
              <horizontal>
                <samples>360</samples>
                <resolution>1</resolution>
                <min_angle>-3.14159</min_angle>
                <max_angle>3.14159</max_angle>
              </horizontal>
            </scan>
            <range>
              <min>0.3</min>
              <max>10</max>
              <resolution>0.01</resolution>
            </range>
            <noise>
              <type>gaussian</type>
              <mean>0</mean>
              <stddev>0.01</stddev>
            </noise>
          </ray>
          <plugin name="gazebo_ros_ray_sensor" filename="libgazebo_ros_ray_sensor.so">
            <ros>
              <remapping>~/out:=scan</remapping>
            </ros>
            <output_type>sensor_msgs/LaserScan</output_type>
            <frame_name>lidar_link</frame_name>
          </plugin>
        </sensor>
      </link>
      
      <!-- Drive wheels (simplified differential drive) -->
      <joint name="left_wheel_joint" type="revolute">
        <parent>base_link</parent>
        <child>left_wheel</child>
        <axis>
          <xyz>0 1 0</xyz>
        </axis>
        <limit>
          <effort>10</effort>
          <velocity>2</velocity>
        </limit>
      </joint>
      <link name="left_wheel">
        <pose relative_to="left_wheel_joint">-0.15 0.17 0 0 0 0</pose>
        <inertial>
          <mass>1</mass>
          <inertia>
            <ixx>0.01</ixx>
            <ixy>0</ixy>
            <ixz>0</ixz>
            <iyy>0.01</iyy>
            <iyz>0</iyz>
            <izz>0.01</izz>
          </inertia>
        </inertial>
        <collision name="collision">
          <geometry>
            <cylinder>
              <radius>0.08</radius>
              <length>0.05</length>
            </cylinder>
          </geometry>
        </collision>
        <visual name="visual">
          <geometry>
            <cylinder>
              <radius>0.08</radius>
              <length>0.05</length>
            </cylinder>
          </geometry>
          <material>
            <script>
              <uri>file://media/materials/scripts/gazebo.material</uri>
              <name>Gazebo/Black</name>
            </script>
          </material>
        </visual>
      </link>
      
      <joint name="right_wheel_joint" type="revolute">
        <parent>base_link</parent>
        <child>right_wheel</child>
        <axis>
          <xyz>0 1 0</xyz>
        </axis>
        <limit>
          <effort>10</effort>
          <velocity>2</velocity>
        </limit>
      </joint>
      <link name="right_wheel">
        <pose relative_to="right_wheel_joint">-0.15 -0.17 0 0 0 0</pose>
        <inertial>
          <mass>1</mass>
          <inertia>
            <ixx>0.01</ixx>
            <ixy>0</ixy>
            <ixz>0</ixz>
            <iyy>0.01</iyy>
            <iyz>0</iyz>
            <izz>0.01</izz>
          </inertia>
        </inertial>
        <collision name="collision">
          <geometry>
            <cylinder>
              <radius>0.08</radius>
              <length>0.05</length>
            </cylinder>
          </geometry>
        </collision>
        <visual name="visual">
          <geometry>
            <cylinder>
              <radius>0.08</radius>
              <length>0.05</length>
            </cylinder>
          </geometry>
          <material>
            <script>
              <uri>file://media/materials/scripts/gazebo.material</uri>
              <name>Gazebo/Black</name>
            </script>
          </material>
        </visual>
      </link>
      
      <!-- Differential drive plugin to convert /cmd_vel to wheel motion -->
      <plugin name="gazebo_ros_diff_drive" filename="libgazebo_ros_diff_drive.so">
        <ros>
          <remapping>cmd_vel:=cmd_vel</remapping>
          <remapping>odom:=odom</remapping>
        </ros>
        <left_joint>left_wheel_joint</left_joint>
        <right_joint>right_wheel_joint</right_joint>
        <wheel_separation>0.34</wheel_separation>
        <wheel_diameter>0.16</wheel_diameter>
        <max_wheel_torque>10</max_wheel_torque>
        <max_wheel_acceleration>3.0</max_wheel_acceleration>
        <odometry_frame>odom</odometry_frame>
        <robot_base_frame>base_link</robot_base_frame>
        <publish_odom>true</publish_odom>
        <publish_odom_tf>true</publish_odom_tf>
        <odometry_topic>odom</odometry_topic>
        <tf_topic>tf</tf_topic>
      </plugin>
    </model>
    
    <!-- Wall obstacles -->
    <model name="wall_north">
      <static>true</static>
      <pose>5 0 0.5 0 0 0</pose>
      <link name="wall_link">
        <collision name="collision">
          <geometry>
            <box>
              <size>0.2 10 1</size>
            </box>
          </geometry>
        </collision>
        <visual name="visual">
          <geometry>
            <box>
              <size>0.2 10 1</size>
            </box>
          </geometry>
          <material>
            <script>
              <uri>file://media/materials/scripts/gazebo.material</uri>
              <name>Gazebo/Red</name>
            </script>
          </material>
        </visual>
      </link>
    </model>
    
    <model name="wall_south">
      <static>true</static>
      <pose>-5 0 0.5 0 0 0</pose>
      <link name="wall_link">
        <collision name="collision">
          <geometry>
            <box>
              <size>0.2 10 1</size>
            </box>
          </geometry>
        </collision>
        <visual name="visual">
          <geometry>
            <box>
              <size>0.2 10 1</size>
            </box>
          </geometry>
          <material>
            <script>
              <uri>file://media/materials/scripts/gazebo.material</uri>
              <name>Gazebo/Red</name>
            </script>
          </material>
        </visual>
      </link>
    </model>
    
    <!-- Random obstacles in the middle -->
    <model name="obstacle_1">
      <static>true</static>
      <pose>2 2 0.5 0 0 0</pose>
      <link name="obstacle_link">
        <collision name="collision">
          <geometry>
            <box>
              <size>1 1 1</size>
            </box>
          </geometry>
        </collision>
        <visual name="visual">
          <geometry>
            <box>
              <size>1 1 1</size>
            </box>
          </geometry>
          <material>
            <script>
              <uri>file://media/materials/scripts/gazebo.material</uri>
              <name>Gazebo/Yellow</name>
            </script>
          </material>
        </visual>
      </link>
    </model>
    
    <model name="obstacle_2">
      <static>true</static>
      <pose>-2 -2 0.5 0 0 0</pose>
      <link name="obstacle_link">
        <collision name="collision">
          <geometry>
            <box>
              <size>1 1 1</size>
            </box>
          </geometry>
        </collision>
        <visual name="visual">
          <geometry>
            <box>
              <size>1 1 1</size>
            </box>
          </geometry>
          <material>
            <script>
              <uri>file://media/materials/scripts/gazebo.material</uri>
              <name>Gazebo/Yellow</name>
            </script>
          </material>
        </visual>
      </link>
    </model>
    
    <model name="obstacle_3">
      <static>true</static>
      <pose>1 -3 0.5 0 0 0</pose>
      <link name="obstacle_link">
        <collision name="collision">
          <geometry>
            <cylinder>
              <radius>0.5</radius>
              <length>1</length>
            </cylinder>
          </geometry>
        </collision>
        <visual name="visual">
          <geometry>
            <cylinder>
              <radius>0.5</radius>
              <length>1</length>
            </cylinder>
          </geometry>
          <material>
            <script>
              <uri>file://media/materials/scripts/gazebo.material</uri>
              <name>Gazebo/Green</name>
            </script>
          </material>
        </visual>
      </link>
    </model>
    
  </world>
</sdf>
